Workbook

Sheet DRE
A1: Fluxos de caixa
C2: Categoria | D2: Receita de vendas | E2: Despesa com serviço de terceiros | F2: Despesa administrativa | G2: Despesa administrativa | H2: Despesa administrativa | I2: IRPJ | J2: Fluxo de caixa de financiamento | K2: Fluxo de caixa de financiamento | L2: Despesa financeira | M2: Captações de empréstimo | N2: Aquisição de ativos - usina solar | P2: DRE | Q2: DRE | R2: DRE | S2: DRE | T2: DRE | U2: DRE | V2: DRE | W2: DRE | X2: DRE | Z2: Fluxo de caixa operacional | AA2: Fluxo de caixa operacional | AB2: Fluxo de caixa investimento | AC2: Fluxo de caixa de financiamento | AD2: Fluxo de caixa de financiamento | AE2: Caixa | AF2: Caixa | AG2: Caixa
C3: Item | D3: Consórcio Zetawatts | E3: Limpeza das placas | F3: Contador | G3: Alvará | H3: JUCERJA | I3: Simples | J3: Parcela do empréstimo | K3: Amortização do empréstimo | L3: Juros | M3: Empréstimo | N3: Usina São Gonçalo I | P3: Lucro bruto | Q3: Despesas operacionais | R3: EBITDA | S3: Depreciação e amortização | T3: EBIT | U3: Despesas financeiras | V3: Lucro antes do imposto de renda | W3: IRPJ | X3: Lucro líquido | Z3: EBIDTA | AA3: Impostos pagos | AB3: Aquisição de ativos | AC3: Captação de empréstimo | AD3: Pagamento de juros e principal | AE3: Resultado líquido | AF3: Saldo inicial | AG3: Saldo final
A4: =YEAR(C4) -> 2021 | B4: ="Q"&(QUOTIENT(MONTH(C4),3.1)+1) -> Q3 | C4: 44409 | F4: 300 | J4: =K4+L4 -> 8645.2403 | K4: =Financiamento!D13 -> 3455.7915 | L4: =Financiamento!C13 -> 5189.4489 | M4: =Financiamento!$B$3 -> 331380.09 | N4: =M4 -> 331380.09 | P4: =D4 -> 0 | Q4: =-SUM(E4:H4) -> -300 | R4: =SUM(P4:Q4) -> -300 | T4: =SUM(R4:S4) -> -300 | U4: =-L4 -> -5189.4489 | V4: =SUM(T4:U4) -> -5489.4489 | W4: =-I4 -> 0 | X4: =SUM(V4:W4) -> -5489.4489 | Z4: =R4 -> -300 | AA4: =W4 -> 0 | AB4: =-N4 -> -331380.09 | AC4: =M4 -> 331380.09 | AD4: =-J4 -> -8645.2403 | AE4: =SUM(Z4:AD4) -> -8945.2403 | AF4: 0 | AG4: =AF4+AE4 -> -8945.2403
A5: =YEAR(C5) -> 2021 | B5: ="Q"&(QUOTIENT(MONTH(C5),3.1)+1) -> Q3 | C5: 44440 | F5: 300 | J5: =K5+L5 -> 8645.2403 | K5: =Financiamento!D14 -> 3509.0106 | L5: =Financiamento!C14 -> 5136.2297 | P5: =D5 -> 0 | Q5: =-SUM(E5:H5) -> -300 | R5: =SUM(P5:Q5) -> -300 | T5: =SUM(R5:S5) -> -300 | U5: =-L5 -> -5136.2297 | V5: =SUM(T5:U5) -> -5436.2297 | W5: =-I5 -> 0 | X5: =SUM(V5:W5) -> -5436.2297 | Z5: =R5 -> -300 | AA5: =W5 -> 0 | AB5: =-N5 -> 0 | AC5: =M5 -> 0 | AD5: =-J5 -> -8645.2403 | AE5: =SUM(Z5:AD5) -> -8945.2403 | AF5: =AG4 -> -8945.2403 | AG5: =AF5+AE5 -> -17890.481
A6: =YEAR(C6) -> 2021 | B6: ="Q"&(QUOTIENT(MONTH(C6),3.1)+1) -> Q4 | C6: 44470 | F6: 300 | J6: =K6+L6 -> 8645.2403 | K6: =Financiamento!D15 -> 3563.0494 | L6: =Financiamento!C15 -> 5082.1909 | P6: =D6 -> 0 | Q6: =-SUM(E6:H6) -> -300 | R6: =SUM(P6:Q6) -> -300 | T6: =SUM(R6:S6) -> -300 | U6: =-L6 -> -5082.1909 | V6: =SUM(T6:U6) -> -5382.1909 | W6: =-I6 -> 0 | X6: =SUM(V6:W6) -> -5382.1909 | Z6: =R6 -> -300 | AA6: =W6 -> 0 | AB6: =-N6 -> 0 | AC6: =M6 -> 0 | AD6: =-J6 -> -8645.2403 | AE6: =SUM(Z6:AD6) -> -8945.2403 | AF6: =AG5 -> -17890.481 | AG6: =AF6+AE6 -> -26835.721
A7: =YEAR(C7) -> 2021 | B7: ="Q"&(QUOTIENT(MONTH(C7),3.1)+1) -> Q4 | C7: 44501 | F7: 300 | J7: =K7+L7 -> 8645.2403 | K7: =Financiamento!D16 -> 3617.9204 | L7: =Financiamento!C16 -> 5027.32 | P7: =D7 -> 0 | Q7: =-SUM(E7:H7) -> -300 | R7: =SUM(P7:Q7) -> -300 | T7: =SUM(R7:S7) -> -300 | U7: =-L7 -> -5027.32 | V7: =SUM(T7:U7) -> -5327.32 | W7: =-I7 -> 0 | X7: =SUM(V7:W7) -> -5327.32 | Z7: =R7 -> -300 | AA7: =W7 -> 0 | AB7: =-N7 -> 0 | AC7: =M7 -> 0 | AD7: =-J7 -> -8645.2403 | AE7: =SUM(Z7:AD7) -> -8945.2403 | AF7: =AG6 -> -26835.721 | AG7: =AF7+AE7 -> -35780.961
A8: =YEAR(C8) -> 2021 | B8: ="Q"&(QUOTIENT(MONTH(C8),3.1)+1) -> Q4 | C8: 44531 | F8: 300 | J8: =K8+L8 -> 8645.2403 | K8: =Financiamento!D17 -> 3673.6363 | L8: =Financiamento!C17 -> 4971.604 | P8: =D8 -> 0 | Q8: =-SUM(E8:H8) -> -300 | R8: =SUM(P8:Q8) -> -300 | T8: =SUM(R8:S8) -> -300 | U8: =-L8 -> -4971.604 | V8: =SUM(T8:U8) -> -5271.604 | W8: =-I8 -> 0 | X8: =SUM(V8:W8) -> -5271.604 | Z8: =R8 -> -300 | AA8: =W8 -> 0 | AB8: =-N8 -> 0 | AC8: =M8 -> 0 | AD8: =-J8 -> -8645.2403 | AE8: =SUM(Z8:AD8) -> -8945.2403 | AF8: =AG7 -> -35780.961 | AG8: =AF8+AE8 -> -44726.202
A9: =YEAR(C9) -> 2022 | B9: ="Q"&(QUOTIENT(MONTH(C9),3.1)+1) -> Q1 | C9: 44562 | F9: 300 | J9: =K9+L9 -> 8645.2403 | K9: =Financiamento!D18 -> 3730.2103 | L9: =Financiamento!C18 -> 4915.03 | P9: =D9 -> 0 | Q9: =-SUM(E9:H9) -> -300 | R9: =SUM(P9:Q9) -> -300 | T9: =SUM(R9:S9) -> -300 | U9: =-L9 -> -4915.03 | V9: =SUM(T9:U9) -> -5215.03 | W9: =-I9 -> 0 | X9: =SUM(V9:W9) -> -5215.03 | Z9: =R9 -> -300 | AA9: =W9 -> 0 | AB9: =-N9 -> 0 | AC9: =M9 -> 0 | AD9: =-J9 -> -8645.2403 | AE9: =SUM(Z9:AD9) -> -8945.2403 | AF9: =AG8 -> -44726.202 | AG9: =AF9+AE9 -> -53671.442
A10: =YEAR(C10) -> 2022 | B10: ="Q"&(QUOTIENT(MONTH(C10),3.1)+1) -> Q1 | C10: 44593 | F10: 300 | J10: =K10+L10 -> 8645.2403 | K10: =Financiamento!D19 -> 3787.6556 | L10: =Financiamento!C19 -> 4857.5848 | P10: =D10 -> 0 | Q10: =-SUM(E10:H10) -> -300 | R10: =SUM(P10:Q10) -> -300 | T10: =SUM(R10:S10) -> -300 | U10: =-L10 -> -4857.5848 | V10: =SUM(T10:U10) -> -5157.5848 | W10: =-I10 -> 0 | X10: =SUM(V10:W10) -> -5157.5848 | Z10: =R10 -> -300 | AA10: =W10 -> 0 | AB10: =-N10 -> 0 | AC10: =M10 -> 0 | AD10: =-J10 -> -8645.2403 | AE10: =SUM(Z10:AD10) -> -8945.2403 | AF10: =AG9 -> -53671.442 | AG10: =AF10+AE10 -> -62616.682
A11: =YEAR(C11) -> 2022 | B11: ="Q"&(QUOTIENT(MONTH(C11),3.1)+1) -> Q1 | C11: 44621 | F11: 300 | J11: =K11+L11 -> 8645.2403 | K11: =Financiamento!D20 -> 3845.9855 | L11: =Financiamento!C20 -> 4799.2549 | P11: =D11 -> 0 | Q11: =-SUM(E11:H11) -> -300 | R11: =SUM(P11:Q11) -> -300 | T11: =SUM(R11:S11) -> -300 | U11: =-L11 -> -4799.2549 | V11: =SUM(T11:U11) -> -5099.2549 | W11: =-I11 -> 0 | X11: =SUM(V11:W11) -> -5099.2549 | Z11: =R11 -> -300 | AA11: =W11 -> 0 | AB11: =-N11 -> 0 | AC11: =M11 -> 0 | AD11: =-J11 -> -8645.2403 | AE11: =SUM(Z11:AD11) -> -8945.2403 | AF11: =AG10 -> -62616.682 | AG11: =AF11+AE11 -> -71561.923
A12: =YEAR(C12) -> 2022 | B12: ="Q"&(QUOTIENT(MONTH(C12),3.1)+1) -> Q2 | C12: 44652 | F12: 300 | J12: =K12+L12 -> 8645.2403 | K12: =Financiamento!D21 -> 3905.2137 | L12: =Financiamento!C21 -> 4740.0267 | P12: =D12 -> 0 | Q12: =-SUM(E12:H12) -> -300 | R12: =SUM(P12:Q12) -> -300 | T12: =SUM(R12:S12) -> -300 | U12: =-L12 -> -4740.0267 | V12: =SUM(T12:U12) -> -5040.0267 | W12: =-I12 -> 0 | X12: =SUM(V12:W12) -> -5040.0267 | Z12: =R12 -> -300 | AA12: =W12 -> 0 | AB12: =-N12 -> 0 | AC12: =M12 -> 0 | AD12: =-J12 -> -8645.2403 | AE12: =SUM(Z12:AD12) -> -8945.2403 | AF12: =AG11 -> -71561.923 | AG12: =AF12+AE12 -> -80507.163
A13: =YEAR(C13) -> 2022 | B13: ="Q"&(QUOTIENT(MONTH(C13),3.1)+1) -> Q2 | C13: 44682 | F13: 300 | J13: =K13+L13 -> 8645.2403 | K13: =Financiamento!D22 -> 3965.354 | L13: =Financiamento!C22 -> 4679.8864 | P13: =D13 -> 0 | Q13: =-SUM(E13:H13) -> -300 | R13: =SUM(P13:Q13) -> -300 | T13: =SUM(R13:S13) -> -300 | U13: =-L13 -> -4679.8864 | V13: =SUM(T13:U13) -> -4979.8864 | W13: =-I13 -> 0 | X13: =SUM(V13:W13) -> -4979.8864 | Z13: =R13 -> -300 | AA13: =W13 -> 0 | AB13: =-N13 -> 0 | AC13: =M13 -> 0 | AD13: =-J13 -> -8645.2403 | AE13: =SUM(Z13:AD13) -> -8945.2403 | AF13: =AG12 -> -80507.163 | AG13: =AF13+AE13 -> -89452.403
A14: =YEAR(C14) -> 2022 | B14: ="Q"&(QUOTIENT(MONTH(C14),3.1)+1) -> Q2 | C14: 44713 | F14: 300 | J14: =K14+L14 -> 8645.2403 | K14: =Financiamento!D23 -> 4026.4204 | L14: =Financiamento!C23 -> 4618.8199 | P14: =D14 -> 0 | Q14: =-SUM(E14:H14) -> -300 | R14: =SUM(P14:Q14) -> -300 | T14: =SUM(R14:S14) -> -300 | U14: =-L14 -> -4618.8199 | V14: =SUM(T14:U14) -> -4918.8199 | W14: =-I14 -> 0 | X14: =SUM(V14:W14) -> -4918.8199 | Z14: =R14 -> -300 | AA14: =W14 -> 0 | AB14: =-N14 -> 0 | AC14: =M14 -> 0 | AD14: =-J14 -> -8645.2403 | AE14: =SUM(Z14:AD14) -> -8945.2403 | AF14: =AG13 -> -89452.403 | AG14: =AF14+AE14 -> -98397.644
A15: =YEAR(C15) -> 2022 | B15: ="Q"&(QUOTIENT(MONTH(C15),3.1)+1) -> Q3 | C15: 44743 | F15: 300 | J15: =K15+L15 -> 8645.2403 | K15: =Financiamento!D24 -> 4088.4273 | L15: =Financiamento!C24 -> 4556.8131 | P15: =D15 -> 0 | Q15: =-SUM(E15:H15) -> -300 | R15: =SUM(P15:Q15) -> -300 | T15: =SUM(R15:S15) -> -300 | U15: =-L15 -> -4556.8131 | V15: =SUM(T15:U15) -> -4856.8131 | W15: =-I15 -> 0 | X15: =SUM(V15:W15) -> -4856.8131 | Z15: =R15 -> -300 | AA15: =W15 -> 0 | AB15: =-N15 -> 0 | AC15: =M15 -> 0 | AD15: =-J15 -> -8645.2403 | AE15: =SUM(Z15:AD15) -> -8945.2403 | AF15: =AG14 -> -98397.644 | AG15: =AF15+AE15 -> -107342.88
A16: =YEAR(C16) -> 2022 | B16: ="Q"&(QUOTIENT(MONTH(C16),3.1)+1) -> Q3 | C16: 44774 | F16: 300 | J16: =K16+L16 -> 8645.2403 | K16: =Financiamento!D25 -> 4151.3891 | L16: =Financiamento!C25 -> 4493.8513 | P16: =D16 -> 0 | Q16: =-SUM(E16:H16) -> -300 | R16: =SUM(P16:Q16) -> -300 | T16: =SUM(R16:S16) -> -300 | U16: =-L16 -> -4493.8513 | V16: =SUM(T16:U16) -> -4793.8513 | W16: =-I16 -> 0 | X16: =SUM(V16:W16) -> -4793.8513 | Z16: =R16 -> -300 | AA16: =W16 -> 0 | AB16: =-N16 -> 0 | AC16: =M16 -> 0 | AD16: =-J16 -> -8645.2403 | AE16: =SUM(Z16:AD16) -> -8945.2403 | AF16: =AG15 -> -107342.88 | AG16: =AF16+AE16 -> -116288.12
... A22: =YEAR(C22) -> 2023 | B22: ="Q"&(QUOTIENT(MONTH(C22),3.1)+1) -> Q1 | C22: 44958 | F22: 300 | J22: =K22+L22 -> 8645.2403 | K22: =Financiamento!D31 -> 4550.0523 | L22: =Financiamento!C31 -> 4095.188 | P22: =D22 -> 0 | Q22: =-SUM(E22:H22) -> -300 | R22: =SUM(P22:Q22) -> -300 | T22: =SUM(R22:S22) -> -300 | U22: =-L22 -> -4095.188 | V22: =SUM(T22:U22) -> -4395.188 | W22: =-I22 -> 0 | X22: =SUM(V22:W22) -> -4395.188 | Z22: =R22 -> -300 | AA22: =W22 -> 0 | AB22: =-N22 -> 0 | AC22: =M22 -> 0 | AD22: =-J22 -> -8645.2403 | AE22: =SUM(Z22:AD22) -> -8945.2403 | AF22: =AG21 -> -161014.33 | AG22: =AF22+AE22 -> -169959.57
A23: =YEAR(C23) -> 2023 | B23: ="Q"&(QUOTIENT(MONTH(C23),3.1)+1) -> Q1 | C23: 44986 | D23: ='Faturamento 235'!P4+'Faturamento Itaipu'!L2+'Faturamento Icaraí'!P2 -> 6633.93 | F23: 300 | I23: =D23*6% -> 398.0358 | J23: =K23+L23 -> 8645.2403 | K23: =Financiamento!D32 -> 4620.1231 | L23: =Financiamento!C32 -> 4025.1172 | P23: =D23 -> 6633.93 | Q23: =-SUM(E23:H23) -> -300 | R23: =SUM(P23:Q23) -> 6333.93 | T23: =SUM(R23:S23) -> 6333.93 | U23: =-L23 -> -4025.1172 | V23: =SUM(T23:U23) -> 2308.8127 | W23: =-I23 -> -398.0358 | X23: =SUM(V23:W23) -> 1910.777 | Z23: =R23 -> 6333.93 | AA23: =W23 -> -398.0358 | AB23: =-N23 -> 0 | AC23: =M23 -> 0 | AD23: =-J23 -> -8645.2403 | AE23: =SUM(Z23:AD23) -> -2709.3462 | AF23: =AG22 -> -169959.57 | AG23: =AF23+AE23 -> -172668.91
A24: =YEAR(C24) -> 2023 | B24: ="Q"&(QUOTIENT(MONTH(C24),3.1)+1) -> Q2 | C24: 45017 | D24: ='Faturamento 235'!P5+'Faturamento Itaipu'!L3+'Faturamento Icaraí'!P3 -> 4801.7427 | F24: 300 | I24: =D24*6% -> 288.10456 | J24: =K24+L24 -> 8645.2403 | K24: =Financiamento!D33 -> 4691.273 | L24: =Financiamento!C33 -> 3953.9673 | P24: =D24 -> 4801.7427 | Q24: =-SUM(E24:H24) -> -300 | R24: =SUM(P24:Q24) -> 4501.7427 | T24: =SUM(R24:S24) -> 4501.7427 | U24: =-L24 -> -3953.9673 | V24: =SUM(T24:U24) -> 547.77538 | W24: =-I24 -> -288.10456 | X24: =SUM(V24:W24) -> 259.67081 | Z24: =R24 -> 4501.7427 | AA24: =W24 -> -288.10456 | AB24: =-N24 -> 0 | AC24: =M24 -> 0 | AD24: =-J24 -> -8645.2403 | AE24: =SUM(Z24:AD24) -> -4431.6022 | AF24: =AG23 -> -172668.91 | AG24: =AF24+AE24 -> -177100.51
A25: =YEAR(C25) -> 2023 | B25: ="Q"&(QUOTIENT(MONTH(C25),3.1)+1) -> Q2 | C25: 45047 | D25: ='Faturamento 235'!P6+'Faturamento Itaipu'!L4+'Faturamento Icaraí'!P4 -> 5583.9064 | F25: 300 | I25: =D25*6% -> 335.03438 | J25: =K25+L25 -> 8645.2403 | K25: =Financiamento!D34 -> 4763.5186 | L25: =Financiamento!C34 -> 3881.7217 | P25: =D25 -> 5583.9064 | Q25: =-SUM(E25:H25) -> -300 | R25: =SUM(P25:Q25) -> 5283.9064 | T25: =SUM(R25:S25) -> 5283.9064 | U25: =-L25 -> -3881.7217 | V25: =SUM(T25:U25) -> 1402.1847 | W25: =-I25 -> -335.03438 | X25: =SUM(V25:W25) -> 1067.1503 | Z25: =R25 -> 5283.9064 | AA25: =W25 -> -335.03438 | AB25: =-N25 -> 0 | AC25: =M25 -> 0 | AD25: =-J25 -> -8645.2403 | AE25: =SUM(Z25:AD25) -> -3696.3683 | AF25: =AG24 -> -177100.51 | AG25: =AF25+AE25 -> -180796.88
A26: =YEAR(C26) -> 2023 | B26: ="Q"&(QUOTIENT(MONTH(C26),3.1)+1) -> Q2 | C26: 45078 | D26: ='Faturamento 235'!P7+'Faturamento Itaipu'!L5+'Faturamento Icaraí'!P5 -> 4018.4622 | F26: 300 | I26: =D26*6% -> 241.10773 | J26: =K26+L26 -> 8645.2403 | K26: =Financiamento!D35 -> 4836.8768 | L26: =Financiamento!C35 -> 3808.3635 | P26: =D26 -> 4018.4622 | Q26: =-SUM(E26:H26) -> -300 | R26: =SUM(P26:Q26) -> 3718.4622 | T26: =SUM(R26:S26) -> 3718.4622 | U26: =-L26 -> -3808.3635 | V26: =SUM(T26:U26) -> -89.901362 | W26: =-I26 -> -241.10773 | X26: =SUM(V26:W26) -> -331.00909 | Z26: =R26 -> 3718.4622 | AA26: =W26 -> -241.10773 | AB26: =-N26 -> 0 | AC26: =M26 -> 0 | AD26: =-J26 -> -8645.2403 | AE26: =SUM(Z26:AD26) -> -5167.8859 | AF26: =AG25 -> -180796.88 | AG26: =AF26+AE26 -> -185964.77
A27: =YEAR(C27) -> 2023 | B27: ="Q"&(QUOTIENT(MONTH(C27),3.1)+1) -> Q3 | C27: 45108 | D27: ='Faturamento 235'!P8+'Faturamento Itaipu'!L6+'Faturamento Icaraí'!P6 -> 3394.6012 | F27: 300 | I27: =D27*6% -> 203.67607 | J27: =K27+L27 -> 8645.2403 | K27: =Financiamento!D36 -> 4911.3647 | L27: =Financiamento!C36 -> 3733.8756 | P27: =D27 -> 3394.6012 | Q27: =-SUM(E27:H27) -> -300 | R27: =SUM(P27:Q27) -> 3094.6012 | T27: =SUM(R27:S27) -> 3094.6012 | U27: =-L27 -> -3733.8756 | V27: =SUM(T27:U27) -> -639.27447 | W27: =-I27 -> -203.67607 | X27: =SUM(V27:W27) -> -842.95054 | Z27: =R27 -> 3094.6012 | AA27: =W27 -> -203.67607 | AB27: =-N27 -> 0 | AC27: =M27 -> 0 | AD27: =-J27 -> -8645.2403 | AE27: =SUM(Z27:AD27) -> -5754.3153 | AF27: =AG26 -> -185964.77 | AG27: =AF27+AE27 -> -191719.08
A28: =YEAR(C28) -> 2023 | B28: ="Q"&(QUOTIENT(MONTH(C28),3.1)+1) -> Q3 | C28: 45139 | D28: ='Faturamento 235'!P9+'Faturamento Itaipu'!L7+'Faturamento Icaraí'!P7 -> 3812.6327 | E28: 1700 | F28: 300 | G28: 236.27 | I28: =D28*6% -> 228.75796 | J28: =K28+L28 -> 8645.2403 | K28: =Financiamento!D37 -> 4986.9997 | L28: =Financiamento!C37 -> 3658.2406 | P28: =D28 -> 3812.6327 | Q28: =-SUM(E28:H28) -> -2236.27 | R28: =SUM(P28:Q28) -> 1576.3627 | T28: =SUM(R28:S28) -> 1576.3627 | U28: =-L28 -> -3658.2406 | V28: =SUM(T28:U28) -> -2081.8779 | W28: =-I28 -> -228.75796 | X28: =SUM(V28:W28) -> -2310.6358 | Z28: =R28 -> 1576.3627 | AA28: =W28 -> -228.75796 | AB28: =-N28 -> 0 | AC28: =M28 -> 0 | AD28: =-J28 -> -8645.2403 | AE28: =SUM(Z28:AD28) -> -7297.6356 | AF28: =AG27 -> -191719.08 | AG28: =AF28+AE28 -> -199016.72
A29: =YEAR(C29) -> 2023 | B29: ="Q"&(QUOTIENT(MONTH(C29),3.1)+1) -> Q3 | C29: 45170 | D29: ='Faturamento 235'!P10+'Faturamento Itaipu'!L8+'Faturamento Icaraí'!P8 -> 4381.9087 | F29: 300 | I29: =D29*6% -> 262.91452 | J29: =K29+L29 -> 8645.2403 | K29: =Financiamento!D38 -> 5063.7995 | L29: =Financiamento!C38 -> 3581.4408 | P29: =D29 -> 4381.9087 | Q29: =-SUM(E29:H29) -> -300 | R29: =SUM(P29:Q29) -> 4081.9087 | T29: =SUM(R29:S29) -> 4081.9087 | U29: =-L29 -> -3581.4408 | V29: =SUM(T29:U29) -> 500.46784 | W29: =-I29 -> -262.91452 | X29: =SUM(V29:W29) -> 237.55332 | Z29: =R29 -> 4081.9087 | AA29: =W29 -> -262.91452 | AB29: =-N29 -> 0 | AC29: =M29 -> 0 | AD29: =-J29 -> -8645.2403 | AE29: =SUM(Z29:AD29) -> -4826.2462 | AF29: =AG28 -> -199016.72 | AG29: =AF29+AE29 -> -203842.97
A30: =YEAR(C30) -> 2023 | B30: ="Q"&(QUOTIENT(MONTH(C30),3.1)+1) -> Q4 | C30: 45200 | D30: ='Faturamento 235'!P11+'Faturamento Itaipu'!L9+'Faturamento Icaraí'!P9 -> 4485.1539 | F30: 300 | I30: =D30*6% -> 269.10923 | J30: =K30+L30 -> 8645.2403 | K30: =Financiamento!D39 -> 5141.782 | L30: =Financiamento!C39 -> 3503.4583 | P30: =D30 -> 4485.1539 | Q30: =-SUM(E30:H30) -> -300 | R30: =SUM(P30:Q30) -> 4185.1539 | T30: =SUM(R30:S30) -> 4185.1539 | U30: =-L30 -> -3503.4583 | V30: =SUM(T30:U30) -> 681.69556 | W30: =-I30 -> -269.10923 | X30: =SUM(V30:W30) -> 412.58633 | Z30: =R30 -> 4185.1539 | AA30: =W30 -> -269.10923 | AB30: =-N30 -> 0 | AC30: =M30 -> 0 | AD30: =-J30 -> -8645.2403 | AE30: =SUM(Z30:AD30) -> -4729.1957 | AF30: =AG29 -> -203842.97 | AG30: =AF30+AE30 -> -208572.16
A31: =YEAR(C31) -> 2023 | B31: ="Q"&(QUOTIENT(MONTH(C31),3.1)+1) -> Q4 | C31: 45231 | D31: ='Faturamento 235'!P12+'Faturamento Itaipu'!L10+'Faturamento Icaraí'!P10 -> 5180.3796 | F31: 300 | I31: =D31*6% -> 310.82278 | J31: =K31+L31 -> 8645.2403 | K31: =Financiamento!D40 -> 5220.9655 | L31: =Financiamento!C40 -> 3424.2749 | P31: =D31 -> 5180.3796 | Q31: =-SUM(E31:H31) -> -300 | R31: =SUM(P31:Q31) -> 4880.3796 | T31: =SUM(R31:S31) -> 4880.3796 | U31: =-L31 -> -3424.2749 | V31: =SUM(T31:U31) -> 1456.1048 | W31: =-I31 -> -310.82278 | X31: =SUM(V31:W31) -> 1145.282 | Z31: =R31 -> 4880.3796 | AA31: =W31 -> -310.82278 | AB31: =-N31 -> 0 | AC31: =M31 -> 0 | AD31: =-J31 -> -8645.2403 | AE31: =SUM(Z31:AD31) -> -4075.6835 | AF31: =AG30 -> -208572.16 | AG31: =AF31+AE31 -> -212647.85
A32: =YEAR(C32) -> 2023 | B32: ="Q"&(QUOTIENT(MONTH(C32),3.1)+1) -> Q4 | C32: 45261 | D32: ='Faturamento 235'!P13+'Faturamento Itaipu'!L11+'Faturamento Icaraí'!P11 -> 4679.9759 | F32: 300 | G32: 1129.75 | H32: 720 | I32: =D32*6% -> 280.79855 | J32: =K32+L32 -> 8645.2403 | K32: =Financiamento!D41 -> 5301.3684 | L32: =Financiamento!C41 -> 3343.872 | P32: =D32 -> 4679.9759 | Q32: =-SUM(E32:H32) -> -2149.75 | R32: =SUM(P32:Q32) -> 2530.2259 | T32: =SUM(R32:S32) -> 2530.2259 | U32: =-L32 -> -3343.872 | V32: =SUM(T32:U32) -> -813.64614 | W32: =-I32 -> -280.79855 | X32: =SUM(V32:W32) -> -1094.4447 | Z32: =R32 -> 2530.2259 | AA32: =W32 -> -280.79855 | AB32: =-N32 -> 0 | AC32: =M32 -> 0 | AD32: =-J32 -> -8645.2403 | AE32: =SUM(Z32:AD32) -> -6395.813 | AF32: =AG31 -> -212647.85 | AG32: =AF32+AE32 -> -219043.66
A33: =YEAR(C33) -> 2024 | B33: ="Q"&(QUOTIENT(MONTH(C33),3.1)+1) -> Q1 | C33: 45292 | D33: ='Faturamento 235'!P14+'Faturamento Itaipu'!L12+'Faturamento Icaraí'!P12 -> 4204.0459 | F33: 300 | I33: =D33*6% -> 252.24275 | J33: =K33+L33 -> 8645.2403 | K33: =Financiamento!D42 -> 5383.0094 | L33: =Financiamento!C42 -> 3262.2309 | P33: =D33 -> 4204.0459 | Q33: =-SUM(E33:H33) -> -300 | R33: =SUM(P33:Q33) -> 3904.0459 | T33: =SUM(R33:S33) -> 3904.0459 | U33: =-L33 -> -3262.2309 | V33: =SUM(T33:U33) -> 641.81497 | W33: =-I33 -> -252.24275 | X33: =SUM(V33:W33) -> 389.57222 | Z33: =R33 -> 3904.0459 | AA33: =W33 -> -252.24275 | AB33: =-N33 -> 0 | AC33: =M33 -> 0 | AD33: =-J33 -> -8645.2403 | AE33: =SUM(Z33:AD33) -> -4993.4372 | AF33: =AG32 -> -219043.66 | AG33: =AF33+AE33 -> -224037.1
A34: =YEAR(C34) -> 2024 | B34: ="Q"&(QUOTIENT(MONTH(C34),3.1)+1) -> Q1 | C34: 45323 | D34: ='Faturamento 235'!P15+'Faturamento Itaipu'!L13+'Faturamento Icaraí'!P13+'Faturamento Laura Jardim'!L2 -> 5809.9943 | F34: 300 | I34: =D34*6% -> 348.59966 | J34: =K34+L34 -> 8645.2403 | K34: =Financiamento!D43 -> 5465.9078 | L34: =Financiamento!C43 -> 3179.3326 | P34: =D34 -> 5809.9943 | Q34: =-SUM(E34:H34) -> -300 | R34: =SUM(P34:Q34) -> 5509.9943 | T34: =SUM(R34:S34) -> 5509.9943 | U34: =-L34 -> -3179.3326 | V34: =SUM(T34:U34) -> 2330.6617 | W34: =-I34 -> -348.59966 | X34: =SUM(V34:W34) -> 1982.0621 | Z34: =R34 -> 5509.9943 | AA34: =W34 -> -348.59966 | AB34: =-N34 -> 0 | AC34: =M34 -> 0 | AD34: =-J34 -> -8645.2403 | AE34: =SUM(Z34:AD34) -> -3483.8457 | AF34: =AG33 -> -224037.1 | AG34: =AF34+AE34 -> -227520.94
A35: =YEAR(C35) -> 2024 | B35: ="Q"&(QUOTIENT(MONTH(C35),3.1)+1) -> Q1 | C35: 45352 | D35: ='Faturamento 235'!P16+'Faturamento Itaipu'!L14+'Faturamento Icaraí'!P14+'Faturamento Laura Jardim'!L3 -> 6923.6927 | F35: 300 | I35: =D35*6% -> 415.42156 | J35: =K35+L35 -> 8645.2403 | K35: =Financiamento!D44 -> 5550.0827 | L35: =Financiamento!C44 -> 3095.1576 | P35: =D35 -> 6923.6927 | Q35: =-SUM(E35:H35) -> -300 | R35: =SUM(P35:Q35) -> 6623.6927 | T35: =SUM(R35:S35) -> 6623.6927 | U35: =-L35 -> -3095.1576 | V35: =SUM(T35:U35) -> 3528.5351 | W35: =-I35 -> -415.42156 | X35: =SUM(V35:W35) -> 3113.1136 | Z35: =R35 -> 6623.6927 | AA35: =W35 -> -415.42156 | AB35: =-N35 -> 0 | AC35: =M35 -> 0 | AD35: =-J35 -> -8645.2403 | AE35: =SUM(Z35:AD35) -> -2436.9692 | AF35: =AG34 -> -227520.94 | AG35: =AF35+AE35 -> -229957.91
A36: =YEAR(C36) -> 2024 | B36: ="Q"&(QUOTIENT(MONTH(C36),3.1)+1) -> Q2 | C36: 45383 | D36: ='Faturamento 235'!P17+'Faturamento Itaipu'!L15+'Faturamento Icaraí'!P15+'Faturamento Laura Jardim'!L4 -> 5791.3046 | F36: 300 | I36: =D36*6% -> 347.47828 | J36: =K36+L36 -> 8645.2403 | K36: =Financiamento!D45 -> 5635.554 | L36: =Financiamento!C45 -> 3009.6863 | P36: =D36 -> 5791.3046 | Q36: =-SUM(E36:H36) -> -300 | R36: =SUM(P36:Q36) -> 5491.3046 | T36: =SUM(R36:S36) -> 5491.3046 | U36: =-L36 -> -3009.6863 | V36: =SUM(T36:U36) -> 2481.6183 | W36: =-I36 -> -347.47828 | X36: =SUM(V36:W36) -> 2134.14 | Z36: =R36 -> 5491.3046 | AA36: =W36 -> -347.47828 | AB36: =-N36 -> 0 | AC36: =M36 -> 0 | AD36: =-J36 -> -8645.2403 | AE36: =SUM(Z36:AD36) -> -3501.414 | AF36: =AG35 -> -229957.91 | AG36: =AF36+AE36 -> -233459.32
A37: =YEAR(C37) -> 2024 | B37: ="Q"&(QUOTIENT(MONTH(C37),3.1)+1) -> Q2 | C37: 45413 | D37: ='Faturamento 235'!P18+'Faturamento Itaipu'!L16+'Faturamento Icaraí'!P16+'Faturamento Laura Jardim'!L5 -> 6448.4677 | F37: 300 | H37: 754 | I37: =D37*6% -> 386.90806 | J37: =K37+L37 -> 8645.2403 | K37: =Financiamento!D46 -> 5722.3416 | L37: =Financiamento!C46 -> 2922.8988 | P37: =D37 -> 6448.4677 | Q37: =-SUM(E37:H37) -> -1054 | R37: =SUM(P37:Q37) -> 5394.4677 | T37: =SUM(R37:S37) -> 5394.4677 | U37: =-L37 -> -2922.8988 | V37: =SUM(T37:U37) -> 2471.5689 | W37: =-I37 -> -386.90806 | X37: =SUM(V37:W37) -> 2084.6608 | Z37: =R37 -> 5394.4677 | AA37: =W37 -> -386.90806 | AB37: =-N37 -> 0 | AC37: =M37 -> 0 | AD37: =-J37 -> -8645.2403 | AE37: =SUM(Z37:AD37) -> -3637.6807 | AF37: =AG36 -> -233459.32 | AG37: =AF37+AE37 -> -237097.01
A38: =YEAR(C38) -> 2024 | B38: ="Q"&(QUOTIENT(MONTH(C38),3.1)+1) -> Q2 | C38: 45444 | D38: ='Faturamento 235'!P19+'Faturamento Itaipu'!L17+'Faturamento Icaraí'!P17+'Faturamento Laura Jardim'!L6 -> 4421.3115 | F38: 300 | I38: =D38*6% -> 265.27869 | J38: =K38+L38 -> 8645.2403 | K38: =Financiamento!D47 -> 5810.4656 | L38: =Financiamento!C47 -> 2834.7747 | P38: =D38 -> 4421.3115 | Q38: =-SUM(E38:H38) -> -300 | R38: =SUM(P38:Q38) -> 4121.3115 | T38: =SUM(R38:S38) -> 4121.3115 | U38: =-L38 -> -2834.7747 | V38: =SUM(T38:U38) -> 1286.5367 | W38: =-I38 -> -265.27869 | X38: =SUM(V38:W38) -> 1021.258 | Z38: =R38 -> 4121.3115 | AA38: =W38 -> -265.27869 | AB38: =-N38 -> 0 | AC38: =M38 -> 0 | AD38: =-J38 -> -8645.2403 | AE38: =SUM(Z38:AD38) -> -4789.2076 | AF38: =AG37 -> -237097.01 | AG38: =AF38+AE38 -> -241886.21
A39: =YEAR(C39) -> 2024 | B39: ="Q"&(QUOTIENT(MONTH(C39),3.1)+1) -> Q3 | C39: 45474 | D39: ='Faturamento 235'!P20+'Faturamento Itaipu'!L18+'Faturamento Icaraí'!P18+'Faturamento Laura Jardim'!L7 -> 3192.3306 | F39: 300 | I39: =D39*6% -> 191.53984 | J39: =K39+L39 -> 8645.2403 | K39: =Financiamento!D48 -> 5899.9468 | L39: =Financiamento!C48 -> 2745.2936 | P39: =D39 -> 3192.3306 | Q39: =-SUM(E39:H39) -> -300 | R39: =SUM(P39:Q39) -> 2892.3306 | T39: =SUM(R39:S39) -> 2892.3306 | U39: =-L39 -> -2745.2936 | V39: =SUM(T39:U39) -> 147.03709 | W39: =-I39 -> -191.53984 | X39: =SUM(V39:W39) -> -44.502746 | Z39: =R39 -> 2892.3306 | AA39: =W39 -> -191.53984 | AB39: =-N39 -> 0 | AC39: =M39 -> 0 | AD39: =-J39 -> -8645.2403 | AE39: =SUM(Z39:AD39) -> -5944.4495 | AF39: =AG38 -> -241886.21 | AG39: =AF39+AE39 -> -247830.66
A40: =YEAR(C40) -> 2024 | B40: ="Q"&(QUOTIENT(MONTH(C40),3.1)+1) -> Q3 | C40: 45505 | D40: ='Faturamento 235'!P21+'Faturamento Itaipu'!L19+'Faturamento Icaraí'!P19+'Faturamento Laura Jardim'!L8+'Faturamento Essencial'!L4 -> 4415.5447 | F40: 300 | I40: =D40*6% -> 264.93268 | J40: =K40+L40 -> 8645.2403 | K40: =Financiamento!D49 -> 5990.806 | L40: =Financiamento!C49 -> 2654.4344 | P40: =D40 -> 4415.5447 | Q40: =-SUM(E40:H40) -> -300 | R40: =SUM(P40:Q40) -> 4115.5447 | T40: =SUM(R40:S40) -> 4115.5447 | U40: =-L40 -> -2654.4344 | V40: =SUM(T40:U40) -> 1461.1103 | W40: =-I40 -> -264.93268 | X40: =SUM(V40:W40) -> 1196.1776 | Z40: =R40 -> 4115.5447 | AA40: =W40 -> -264.93268 | AB40: =-N40 -> 0 | AC40: =M40 -> 0 | AD40: =-J40 -> -8645.2403 | AE40: =SUM(Z40:AD40) -> -4794.6283 | AF40: =AG39 -> -247830.66 | AG40: =AF40+AE40 -> -252625.29
A41: =YEAR(C41) -> 2024 | B41: ="Q"&(QUOTIENT(MONTH(C41),3.1)+1) -> Q3 | C41: 45536 | D41: ='Faturamento 235'!P22+'Faturamento Itaipu'!L20+'Faturamento Icaraí'!P20+'Faturamento Laura Jardim'!L9+'Faturamento Essencial'!L5 -> 6035.7282 | F41: 300 | I41: =D41*6% -> 362.14369 | J41: =K41+L41 -> 8645.2403 | K41: =Financiamento!D50 -> 6083.0644 | L41: =Financiamento!C50 -> 2562.176 | P41: =D41 -> 6035.7282 | Q41: =-SUM(E41:H41) -> -300 | R41: =SUM(P41:Q41) -> 5735.7282 | T41: =SUM(R41:S41) -> 5735.7282 | U41: =-L41 -> -2562.176 | V41: =SUM(T41:U41) -> 3173.5523 | W41: =-I41 -> -362.14369 | X41: =SUM(V41:W41) -> 2811.4086 | Z41: =R41 -> 5735.7282 | AA41: =W41 -> -362.14369 | AB41: =-N41 -> 0 | AC41: =M41 -> 0 | AD41: =-J41 -> -8645.2403 | AE41: =SUM(Z41:AD41) -> -3271.6558 | AF41: =AG40 -> -252625.29 | AG41: =AF41+AE41 -> -255896.95
A42: =YEAR(C42) -> 2024 | B42: ="Q"&(QUOTIENT(MONTH(C42),3.1)+1) -> Q4 | C42: 45566 | D42: ='Faturamento 235'!P23+'Faturamento Itaipu'!L21+'Faturamento Icaraí'!P21+'Faturamento Laura Jardim'!L10+'Faturamento Essencial'!L6 -> 5693.1627 | F42: 300 | I42: =D42*6% -> 341.58976 | J42: =K42+L42 -> 8645.2403 | K42: =Financiamento!D51 -> 6176.7436 | L42: =Financiamento!C51 -> 2468.4968 | P42: =D42 -> 5693.1627 | Q42: =-SUM(E42:H42) -> -300 | R42: =SUM(P42:Q42) -> 5393.1627 | T42: =SUM(R42:S42) -> 5393.1627 | U42: =-L42 -> -2468.4968 | V42: =SUM(T42:U42) -> 2924.666 | W42: =-I42 -> -341.58976 | X42: =SUM(V42:W42) -> 2583.0762 | Z42: =R42 -> 5393.1627 | AA42: =W42 -> -341.58976 | AB42: =-N42 -> 0 | AC42: =M42 -> 0 | AD42: =-J42 -> -8645.2403 | AE42: =SUM(Z42:AD42) -> -3593.6674 | AF42: =AG41 -> -255896.95 | AG42: =AF42+AE42 -> -259490.61
A43: =YEAR(C43) -> 2024 | B43: ="Q"&(QUOTIENT(MONTH(C43),3.1)+1) -> Q4 | C43: 45597 | D43: ='Faturamento 235'!P24+'Faturamento Itaipu'!L22+'Faturamento Icaraí'!P22+'Faturamento Laura Jardim'!L11+'Faturamento Essencial'!L7+'Faturamento 281'!N24 -> 8410.5282 | F43: 300 | I43: =D43*6% -> 504.63169 | J43: =K43+L43 -> 8645.2403 | K43: =Financiamento!D52 -> 6271.8654 | L43: =Financiamento!C52 -> 2373.3749 | P43: =D43 -> 8410.5282 | Q43: =-SUM(E43:H43) -> -300 | R43: =SUM(P43:Q43) -> 8110.5282 | T43: =SUM(R43:S43) -> 8110.5282 | U43: =-L43 -> -2373.3749 | V43: =SUM(T43:U43) -> 5737.1533 | W43: =-I43 -> -504.63169 | X43: =SUM(V43:W43) -> 5232.5216 | Z43: =R43 -> 8110.5282 | AA43: =W43 -> -504.63169 | AB43: =-N43 -> 0 | AC43: =M43 -> 0 | AD43: =-J43 -> -8645.2403 | AE43: =SUM(Z43:AD43) -> -1039.3438 | AF43: =AG42 -> -259490.61 | AG43: =AF43+AE43 -> -260529.96
A44: =YEAR(C44) -> 2024 | B44: ="Q"&(QUOTIENT(MONTH(C44),3.1)+1) -> Q4 | C44: 45627 | D44: ='Faturamento 235'!P25+'Faturamento Itaipu'!L23+'Faturamento Icaraí'!P23+'Faturamento Laura Jardim'!L12+'Faturamento Essencial'!L8+'Faturamento 281'!N25 -> 6666.4636 | F44: 300 | I44: =D44*6% -> 399.98782 | J44: =K44+L44 -> 8645.2403 | K44: =Financiamento!D53 -> 6368.4521 | L44: =Financiamento!C53 -> 2276.7882 | P44: =D44 -> 6666.4636 | Q44: =-SUM(E44:H44) -> -300 | R44: =SUM(P44:Q44) -> 6366.4636 | T44: =SUM(R44:S44) -> 6366.4636 | U44: =-L44 -> -2276.7882 | V44: =SUM(T44:U44) -> 4089.6754 | W44: =-I44 -> -399.98782 | X44: =SUM(V44:W44) -> 3689.6876 | Z44: =R44 -> 6366.4636 | AA44: =W44 -> -399.98782 | AB44: =-N44 -> 0 | AC44: =M44 -> 0 | AD44: =-J44 -> -8645.2403 | AE44: =SUM(Z44:AD44) -> -2678.7645 | AF44: =AG43 -> -260529.96 | AG44: =AF44+AE44 -> -263208.72
A45: =YEAR(C45) -> 2025 | B45: ="Q"&(QUOTIENT(MONTH(C45),3.1)+1) -> Q1 | C45: 45658 | D45: ='Faturamento 235'!P26+'Faturamento Itaipu'!L24+'Faturamento Icaraí'!P24+'Faturamento Laura Jardim'!L13+'Faturamento Essencial'!L9+'Faturamento 281'!N26 -> 7369.6552 | F45: 300 | I45: =D45*6% -> 442.17931 | J45: =K45+L45 -> 8645.2403 | K45: =Financiamento!D54 -> 6466.5263 | L45: =Financiamento!C54 -> 2178.714 | P45: =D45 -> 7369.6552 | Q45: =-SUM(E45:H45) -> -300 | R45: =SUM(P45:Q45) -> 7069.6552 | T45: =SUM(R45:S45) -> 7069.6552 | U45: =-L45 -> -2178.714 | V45: =SUM(T45:U45) -> 4890.9412 | W45: =-I45 -> -442.17931 | X45: =SUM(V45:W45) -> 4448.7618 | Z45: =R45 -> 7069.6552 | AA45: =W45 -> -442.17931 | AB45: =-N45 -> 0 | AC45: =M45 -> 0 | AD45: =-J45 -> -8645.2403 | AE45: =SUM(Z45:AD45) -> -2017.7645 | AF45: =AG44 -> -263208.72 | AG45: =AF45+AE45 -> -265226.49
...

Sheet Projeção
A1: Fluxos de caixa | Q1: DRE | AA1: Fluxo de caixa
C2: Categoria | D2: Receita de vendas | E2: Receita de vendas | F2: Despesa com serviço de terceiros | G2: Despesa administrativa | H2: Despesa administrativa | I2: Despesa administrativa | J2: IRPJ | M2: Despesa financeira | N2: Captações de empréstimo | O2: Aquisição de ativos | AA2: Fluxo de caixa operacional | AB2: Fluxo de caixa investimento | AC2: Fluxo de caixa de financiamento | AD2: Fluxo de caixa de financiamento | AE2: Caixa | AF2: Caixa | AG2: Caixa
C3: Item | D3: Consórcio Zetawatts | E3: BOT P Kennedy | F3: Limpeza das placas | G3: Contador | H3: Alvará | I3: JUCERJA | J3: Simples | K3: Parcela do empréstimo | L3: Amortização do empréstimo | M3: Juros | N3: Empréstimo | O3: Usinas solares | Q3: Receitas | R3: Despesas operacionais | S3: EBITDA | T3: Depreciação e amortização | U3: EBIT | V3: Despesas financeiras | W3: Lucro antes do imposto de renda | X3: IRPJ | Y3: Lucro líquido | AA3: EBIDTA | AB3: Aquisição de ativos | AC3: Captação de empréstimo | AD3: Pagamento de juros e principal | AE3: Resultado líquido | AF3: Saldo inicial | AG3: Saldo final | AJ3: Receita | AK3: Lucro líquido | AL3: EBITDA | AM3: Fluxo de caixa líquido | AN3: Saldo em caixa | AQ3: Fluxo de Caixa - APAGAR | AR3: Fluxo de Caixa Ideal
A4: =YEAR(C4) -> 2021 | B4: ="Q"&(QUOTIENT(MONTH(C4),3.1)+1) -> Q3 | C4: 44409 | G4: 300 | K4: =L4+M4 -> 8645.2403 | L4: =Financiamento!D13 -> 3455.7915 | M4: =Financiamento!C13 -> 5189.4489 | N4: =Financiamento!$B$3 -> 331380.09 | O4: =N4 -> 331380.09 | Q4: =D4 -> 0 | R4: =-SUM(F4:I4) -> -300 | S4: =SUM(Q4:R4) -> -300 | U4: =SUM(S4:T4) -> -300 | V4: =-M4 -> -5189.4489 | W4: =SUM(U4:V4) -> -5489.4489 | X4: =-J4 -> 0 | Y4: =SUM(W4:X4) -> -5489.4489 | AA4: =S4 -> -300 | AB4: =-O4 -> -331380.09 | AC4: =N4 -> 331380.09 | AD4: =-K4 -> -8645.2403 | AE4: =SUM(AA4:AD4) -> -8945.2403 | AF4: 0 | AG4: =AF4+AE4 -> -8945.2403 | AI4: 2021 | AJ4: =SUMIFS($Q$4:$Q$176,$A$4:$A$176,$AI4) -> 0 | AK4: =SUMIFS($Y$4:$Y$176,$A$4:$A$176,$AI4) -> -26906.793 | AL4: =SUMIFS($S$4:$S$176,$A$4:$A$176,$AI4) -> -1500 | AM4: =SUMIFS($AE$4:$AE$176,$A$4:$A$176,$AI4) -> -44726.202 | AN4: {=XLOOKUP(AI4&12,$A$4:$A$176&MONTH($C$4:$C$176),$AG$4:$AG$176)} -> #NAME? | AQ4: =AE4 -> -8945.2403 | AR4: =AQ4 -> -8945.2403
A5: =YEAR(C5) -> 2021 | B5: ="Q"&(QUOTIENT(MONTH(C5),3.1)+1) -> Q3 | C5: 44440 | G5: 300 | K5: =L5+M5 -> 8645.2403 | L5: =Financiamento!D14 -> 3509.0106 | M5: =Financiamento!C14 -> 5136.2297 | Q5: =D5 -> 0 | R5: =-SUM(F5:I5) -> -300 | S5: =SUM(Q5:R5) -> -300 | U5: =SUM(S5:T5) -> -300 | V5: =-M5 -> -5136.2297 | W5: =SUM(U5:V5) -> -5436.2297 | X5: =-J5 -> 0 | Y5: =SUM(W5:X5) -> -5436.2297 | AA5: =S5 -> -300 | AB5: =-O5 -> 0 | AC5: =N5 -> 0 | AD5: =-K5 -> -8645.2403 | AE5: =SUM(AA5:AD5) -> -8945.2403 | AF5: =AG4 -> -8945.2403 | AG5: =AF5+AE5 -> -17890.481 | AI5: 2022 | AJ5: =SUMIFS($Q$4:$Q$176,$A$4:$A$176,$AI5) -> 0 | AK5: =SUMIFS($Y$4:$Y$176,$A$4:$A$176,$AI5) -> -58587.437 | AL5: =SUMIFS($S$4:$S$176,$A$4:$A$176,$AI5) -> -3600 | AM5: =SUMIFS($AE$4:$AE$176,$A$4:$A$176,$AI5) -> -107342.88 | AN5: {=XLOOKUP(AI5&12,$A$4:$A$176&MONTH($C$4:$C$176),$AG$4:$AG$176)} -> #NAME? | AQ5: =AE5 -> -8945.2403 | AR5: =AQ5 -> -8945.2403
A6: =YEAR(C6) -> 2021 | B6: ="Q"&(QUOTIENT(MONTH(C6),3.1)+1) -> Q4 | C6: 44470 | G6: 300 | K6: =L6+M6 -> 8645.2403 | L6: =Financiamento!D15 -> 3563.0494 | M6: =Financiamento!C15 -> 5082.1909 | Q6: =D6 -> 0 | R6: =-SUM(F6:I6) -> -300 | S6: =SUM(Q6:R6) -> -300 | U6: =SUM(S6:T6) -> -300 | V6: =-M6 -> -5082.1909 | W6: =SUM(U6:V6) -> -5382.1909 | X6: =-J6 -> 0 | Y6: =SUM(W6:X6) -> -5382.1909 | AA6: =S6 -> -300 | AB6: =-O6 -> 0 | AC6: =N6 -> 0 | AD6: =-K6 -> -8645.2403 | AE6: =SUM(AA6:AD6) -> -8945.2403 | AF6: =AG5 -> -17890.481 | AG6: =AF6+AE6 -> -26835.721 | AI6: 2023 | AJ6: =SUMIFS($Q$4:$Q$176,$A$4:$A$176,$AI6) -> 46972.693 | AK6: =SUMIFS($Y$4:$Y$176,$A$4:$A$176,$AI6) -> -8405.4046 | AL6: =SUMIFS($S$4:$S$176,$A$4:$A$176,$AI6) -> 39586.673 | AM6: =SUMIFS($AE$4:$AE$176,$A$4:$A$176,$AI6) -> -64156.211 | AN6: {=XLOOKUP(AI6&12,$A$4:$A$176&MONTH($C$4:$C$176),$AG$4:$AG$176)} -> #NAME? | AQ6: =AE6 -> -8945.2403 | AR6: =AQ6 -> -8945.2403
A7: =YEAR(C7) -> 2021 | B7: ="Q"&(QUOTIENT(MONTH(C7),3.1)+1) -> Q4 | C7: 44501 | G7: 300 | K7: =L7+M7 -> 8645.2403 | L7: =Financiamento!D16 -> 3617.9204 | M7: =Financiamento!C16 -> 5027.32 | Q7: =D7 -> 0 | R7: =-SUM(F7:I7) -> -300 | S7: =SUM(Q7:R7) -> -300 | U7: =SUM(S7:T7) -> -300 | V7: =-M7 -> -5027.32 | W7: =SUM(U7:V7) -> -5327.32 | X7: =-J7 -> 0 | Y7: =SUM(W7:X7) -> -5327.32 | AA7: =S7 -> -300 | AB7: =-O7 -> 0 | AC7: =N7 -> 0 | AD7: =-K7 -> -8645.2403 | AE7: =SUM(AA7:AD7) -> -8945.2403 | AF7: =AG6 -> -26835.721 | AG7: =AF7+AE7 -> -35780.961 | AI7: 2024 | AJ7: =SUMIFS($Q$4:$Q$176,$A$4:$A$176,$AI7) -> 68012.575 | AK7: =SUMIFS($Y$4:$Y$176,$A$4:$A$176,$AI7) -> 26193.176 | AL7: =SUMIFS($S$4:$S$176,$A$4:$A$176,$AI7) -> 63658.575 | AM7: =SUMIFS($AE$4:$AE$176,$A$4:$A$176,$AI7) -> -40084.309 | AN7: {=XLOOKUP(AI7&12,$A$4:$A$176&MONTH($C$4:$C$176),$AG$4:$AG$176)} -> #NAME? | AQ7: =AE7 -> -8945.2403 | AR7: =AQ7 -> -8945.2403
A8: =YEAR(C8) -> 2021 | B8: ="Q"&(QUOTIENT(MONTH(C8),3.1)+1) -> Q4 | C8: 44531 | G8: 300 | K8: =L8+M8 -> 8645.2403 | L8: =Financiamento!D17 -> 3673.6363 | M8: =Financiamento!C17 -> 4971.604 | Q8: =D8 -> 0 | R8: =-SUM(F8:I8) -> -300 | S8: =SUM(Q8:R8) -> -300 | U8: =SUM(S8:T8) -> -300 | V8: =-M8 -> -4971.604 | W8: =SUM(U8:V8) -> -5271.604 | X8: =-J8 -> 0 | Y8: =SUM(W8:X8) -> -5271.604 | AA8: =S8 -> -300 | AB8: =-O8 -> 0 | AC8: =N8 -> 0 | AD8: =-K8 -> -8645.2403 | AE8: =SUM(AA8:AD8) -> -8945.2403 | AF8: =AG7 -> -35780.961 | AG8: =AF8+AE8 -> -44726.202 | AI8: 2025 | AJ8: =SUMIFS($Q$4:$Q$176,$A$4:$A$176,$AI8) -> 97270.247 | AK8: =SUMIFS($Y$4:$Y$176,$A$4:$A$176,$AI8) -> 64451.602 | AL8: =SUMIFS($S$4:$S$176,$A$4:$A$176,$AI8) -> 93370.247 | AM8: =SUMIFS($AE$4:$AE$176,$A$4:$A$176,$AI8) -> -19017.878 | AN8: {=XLOOKUP(AI8&12,$A$4:$A$176&MONTH($C$4:$C$176),$AG$4:$AG$176)} -> #NAME? | AQ8: =AE8 -> -8945.2403 | AR8: =AQ8 -> -8945.2403
A9: =YEAR(C9) -> 2022 | B9: ="Q"&(QUOTIENT(MONTH(C9),3.1)+1) -> Q1 | C9: 44562 | G9: 300 | K9: =L9+M9 -> 8645.2403 | L9: =Financiamento!D18 -> 3730.2103 | M9: =Financiamento!C18 -> 4915.03 | Q9: =D9 -> 0 | R9: =-SUM(F9:I9) -> -300 | S9: =SUM(Q9:R9) -> -300 | U9: =SUM(S9:T9) -> -300 | V9: =-M9 -> -4915.03 | W9: =SUM(U9:V9) -> -5215.03 | X9: =-J9 -> 0 | Y9: =SUM(W9:X9) -> -5215.03 | AA9: =S9 -> -300 | AB9: =-O9 -> 0 | AC9: =N9 -> 0 | AD9: =-K9 -> -8645.2403 | AE9: =SUM(AA9:AD9) -> -8945.2403 | AF9: =AG8 -> -44726.202 | AG9: =AF9+AE9 -> -53671.442 | AI9: 2026 | AJ9: =SUMIFS($Q$4:$Q$176,$A$4:$A$176,$AI9) -> #NAME? | AK9: =SUMIFS($Y$4:$Y$176,$A$4:$A$176,$AI9) -> #NAME? | AL9: =SUMIFS($S$4:$S$176,$A$4:$A$176,$AI9) -> #NAME? | AM9: =SUMIFS($AE$4:$AE$176,$A$4:$A$176,$AI9) -> #NAME? | AN9: {=XLOOKUP(AI9&12,$A$4:$A$176&MONTH($C$4:$C$176),$AG$4:$AG$176)} -> #NAME? | AQ9: =AE9 -> -8945.2403 | AR9: =AQ9 -> -8945.2403
A10: =YEAR(C10) -> 2022 | B10: ="Q"&(QUOTIENT(MONTH(C10),3.1)+1) -> Q1 | C10: 44593 | G10: 300 | K10: =L10+M10 -> 8645.2403 | L10: =Financiamento!D19 -> 3787.6556 | M10: =Financiamento!C19 -> 4857.5848 | Q10: =D10 -> 0 | R10: =-SUM(F10:I10) -> -300 | S10: =SUM(Q10:R10) -> -300 | U10: =SUM(S10:T10) -> -300 | V10: =-M10 -> -4857.5848 | W10: =SUM(U10:V10) -> -5157.5848 | X10: =-J10 -> 0 | Y10: =SUM(W10:X10) -> -5157.5848 | AA10: =S10 -> -300 | AB10: =-O10 -> 0 | AC10: =N10 -> 0 | AD10: =-K10 -> -8645.2403 | AE10: =SUM(AA10:AD10) -> -8945.2403 | AF10: =AG9 -> -53671.442 | AG10: =AF10+AE10 -> -62616.682 | AI10: 2027 | AJ10: =SUMIFS($Q$4:$Q$176,$A$4:$A$176,$AI10) -> #NAME? | AK10: =SUMIFS($Y$4:$Y$176,$A$4:$A$176,$AI10) -> #NAME? | AL10: =SUMIFS($S$4:$S$176,$A$4:$A$176,$AI10) -> #NAME? | AM10: =SUMIFS($AE$4:$AE$176,$A$4:$A$176,$AI10) -> #NAME? | AN10: {=XLOOKUP(AI10&12,$A$4:$A$176&MONTH($C$4:$C$176),$AG$4:$AG$176)} -> #NAME? | AQ10: =AE10 -> -8945.2403 | AR10: =AQ10 -> -8945.2403
A11: =YEAR(C11) -> 2022 | B11: ="Q"&(QUOTIENT(MONTH(C11),3.1)+1) -> Q1 | C11: 44621 | G11: 300 | K11: =L11+M11 -> 8645.2403 | L11: =Financiamento!D20 -> 3845.9855 | M11: =Financiamento!C20 -> 4799.2549 | Q11: =D11 -> 0 | R11: =-SUM(F11:I11) -> -300 | S11: =SUM(Q11:R11) -> -300 | U11: =SUM(S11:T11) -> -300 | V11: =-M11 -> -4799.2549 | W11: =SUM(U11:V11) -> -5099.2549 | X11: =-J11 -> 0 | Y11: =SUM(W11:X11) -> -5099.2549 | AA11: =S11 -> -300 | AB11: =-O11 -> 0 | AC11: =N11 -> 0 | AD11: =-K11 -> -8645.2403 | AE11: =SUM(AA11:AD11) -> -8945.2403 | AF11: =AG10 -> -62616.682 | AG11: =AF11+AE11 -> -71561.923 | AI11: 2028 | AJ11: =SUMIFS($Q$4:$Q$176,$A$4:$A$176,$AI11) -> #NAME? | AK11: =SUMIFS($Y$4:$Y$176,$A$4:$A$176,$AI11) -> #NAME? | AL11: =SUMIFS($S$4:$S$176,$A$4:$A$176,$AI11) -> #NAME? | AM11: =SUMIFS($AE$4:$AE$176,$A$4:$A$176,$AI11) -> #NAME? | AN11: {=XLOOKUP(AI11&12,$A$4:$A$176&MONTH($C$4:$C$176),$AG$4:$AG$176)} -> #NAME? | AQ11: =AE11 -> -8945.2403 | AR11: =AQ11 -> -8945.2403
A12: =YEAR(C12) -> 2022 | B12: ="Q"&(QUOTIENT(MONTH(C12),3.1)+1) -> Q2 | C12: 44652 | G12: 300 | K12: =L12+M12 -> 8645.2403 | L12: =Financiamento!D21 -> 3905.2137 | M12: =Financiamento!C21 -> 4740.0267 | Q12: =D12 -> 0 | R12: =-SUM(F12:I12) -> -300 | S12: =SUM(Q12:R12) -> -300 | U12: =SUM(S12:T12) -> -300 | V12: =-M12 -> -4740.0267 | W12: =SUM(U12:V12) -> -5040.0267 | X12: =-J12 -> 0 | Y12: =SUM(W12:X12) -> -5040.0267 | AA12: =S12 -> -300 | AB12: =-O12 -> 0 | AC12: =N12 -> 0 | AD12: =-K12 -> -8645.2403 | AE12: =SUM(AA12:AD12) -> -8945.2403 | AF12: =AG11 -> -71561.923 | AG12: =AF12+AE12 -> -80507.163 | AI12: 2029 | AJ12: =SUMIFS($Q$4:$Q$176,$A$4:$A$176,$AI12) -> #NAME? | AK12: =SUMIFS($Y$4:$Y$176,$A$4:$A$176,$AI12) -> #NAME? | AL12: =SUMIFS($S$4:$S$176,$A$4:$A$176,$AI12) -> #NAME? | AM12: =SUMIFS($AE$4:$AE$176,$A$4:$A$176,$AI12) -> #NAME? | AN12: {=XLOOKUP(AI12&12,$A$4:$A$176&MONTH($C$4:$C$176),$AG$4:$AG$176)} -> #NAME? | AQ12: =AE12 -> -8945.2403 | AR12: =AQ12 -> -8945.2403
A13: =YEAR(C13) -> 2022 | B13: ="Q"&(QUOTIENT(MONTH(C13),3.1)+1) -> Q2 | C13: 44682 | G13: 300 | K13: =L13+M13 -> 8645.2403 | L13: =Financiamento!D22 -> 3965.354 | M13: =Financiamento!C22 -> 4679.8864 | Q13: =D13 -> 0 | R13: =-SUM(F13:I13) -> -300 | S13: =SUM(Q13:R13) -> -300 | U13: =SUM(S13:T13) -> -300 | V13: =-M13 -> -4679.8864 | W13: =SUM(U13:V13) -> -4979.8864 | X13: =-J13 -> 0 | Y13: =SUM(W13:X13) -> -4979.8864 | AA13: =S13 -> -300 | AB13: =-O13 -> 0 | AC13: =N13 -> 0 | AD13: =-K13 -> -8645.2403 | AE13: =SUM(AA13:AD13) -> -8945.2403 | AF13: =AG12 -> -80507.163 | AG13: =AF13+AE13 -> -89452.403 | AI13: 2030 | AJ13: =SUMIFS($Q$4:$Q$176,$A$4:$A$176,$AI13) -> #NAME? | AK13: =SUMIFS($Y$4:$Y$176,$A$4:$A$176,$AI13) -> #NAME? | AL13: =SUMIFS($S$4:$S$176,$A$4:$A$176,$AI13) -> #NAME? | AM13: =SUMIFS($AE$4:$AE$176,$A$4:$A$176,$AI13) -> #NAME? | AN13: {=XLOOKUP(AI13&12,$A$4:$A$176&MONTH($C$4:$C$176),$AG$4:$AG$176)} -> #NAME? | AQ13: =AE13 -> -8945.2403 | AR13: =AQ13 -> -8945.2403
A14: =YEAR(C14) -> 2022 | B14: ="Q"&(QUOTIENT(MONTH(C14),3.1)+1) -> Q2 | C14: 44713 | G14: 300 | K14: =L14+M14 -> 8645.2403 | L14: =Financiamento!D23 -> 4026.4204 | M14: =Financiamento!C23 -> 4618.8199 | Q14: =D14 -> 0 | R14: =-SUM(F14:I14) -> -300 | S14: =SUM(Q14:R14) -> -300 | U14: =SUM(S14:T14) -> -300 | V14: =-M14 -> -4618.8199 | W14: =SUM(U14:V14) -> -4918.8199 | X14: =-J14 -> 0 | Y14: =SUM(W14:X14) -> -4918.8199 | AA14: =S14 -> -300 | AB14: =-O14 -> 0 | AC14: =N14 -> 0 | AD14: =-K14 -> -8645.2403 | AE14: =SUM(AA14:AD14) -> -8945.2403 | AF14: =AG13 -> -89452.403 | AG14: =AF14+AE14 -> -98397.644 | AI14: 2031 | AJ14: =SUMIFS($Q$4:$Q$176,$A$4:$A$176,$AI14) -> #NAME? | AK14: =SUMIFS($Y$4:$Y$176,$A$4:$A$176,$AI14) -> #NAME? | AL14: =SUMIFS($S$4:$S$176,$A$4:$A$176,$AI14) -> #NAME? | AM14: =SUMIFS($AE$4:$AE$176,$A$4:$A$176,$AI14) -> #NAME? | AN14: {=XLOOKUP(AI14&12,$A$4:$A$176&MONTH($C$4:$C$176),$AG$4:$AG$176)} -> #NAME? | AQ14: =AE14 -> -8945.2403 | AR14: =AQ14 -> -8945.2403
A15: =YEAR(C15) -> 2022 | B15: ="Q"&(QUOTIENT(MONTH(C15),3.1)+1) -> Q3 | C15: 44743 | G15: 300 | K15: =L15+M15 -> 8645.2403 | L15: =Financiamento!D24 -> 4088.4273 | M15: =Financiamento!C24 -> 4556.8131 | Q15: =D15 -> 0 | R15: =-SUM(F15:I15) -> -300 | S15: =SUM(Q15:R15) -> -300 | U15: =SUM(S15:T15) -> -300 | V15: =-M15 -> -4556.8131 | W15: =SUM(U15:V15) -> -4856.8131 | X15: =-J15 -> 0 | Y15: =SUM(W15:X15) -> -4856.8131 | AA15: =S15 -> -300 | AB15: =-O15 -> 0 | AC15: =N15 -> 0 | AD15: =-K15 -> -8645.2403 | AE15: =SUM(AA15:AD15) -> -8945.2403 | AF15: =AG14 -> -98397.644 | AG15: =AF15+AE15 -> -107342.88 | AI15: 2032 | AJ15: =SUMIFS($Q$4:$Q$176,$A$4:$A$176,$AI15) -> #NAME? | AK15: =SUMIFS($Y$4:$Y$176,$A$4:$A$176,$AI15) -> #NAME? | AL15: =SUMIFS($S$4:$S$176,$A$4:$A$176,$AI15) -> #NAME? | AM15: =SUMIFS($AE$4:$AE$176,$A$4:$A$176,$AI15) -> #NAME? | AN15: {=XLOOKUP(AI15&12,$A$4:$A$176&MONTH($C$4:$C$176),$AG$4:$AG$176)} -> #NAME? | AQ15: =AE15 -> -8945.2403 | AR15: =AQ15 -> -8945.2403
A16: =YEAR(C16) -> 2022 | B16: ="Q"&(QUOTIENT(MONTH(C16),3.1)+1) -> Q3 | C16: 44774 | G16: 300 | K16: =L16+M16 -> 8645.2403 | L16: =Financiamento!D25 -> 4151.3891 | M16: =Financiamento!C25 -> 4493.8513 | Q16: =D16 -> 0 | R16: =-SUM(F16:I16) -> -300 | S16: =SUM(Q16:R16) -> -300 | U16: =SUM(S16:T16) -> -300 | V16: =-M16 -> -4493.8513 | W16: =SUM(U16:V16) -> -4793.8513 | X16: =-J16 -> 0 | Y16: =SUM(W16:X16) -> -4793.8513 | AA16: =S16 -> -300 | AB16: =-O16 -> 0 | AC16: =N16 -> 0 | AD16: =-K16 -> -8645.2403 | AE16: =SUM(AA16:AD16) -> -8945.2403 | AF16: =AG15 -> -107342.88 | AG16: =AF16+AE16 -> -116288.12 | AI16: 2033 | AJ16: =SUMIFS($Q$4:$Q$176,$A$4:$A$176,$AI16) -> #NAME? | AK16: =SUMIFS($Y$4:$Y$176,$A$4:$A$176,$AI16) -> #NAME? | AL16: =SUMIFS($S$4:$S$176,$A$4:$A$176,$AI16) -> #NAME? | AM16: =SUMIFS($AE$4:$AE$176,$A$4:$A$176,$AI16) -> #NAME? | AN16: {=XLOOKUP(AI16&12,$A$4:$A$176&MONTH($C$4:$C$176),$AG$4:$AG$176)} -> #NAME? | AQ16: =AE16 -> -8945.2403 | AR16: =AQ16 -> -8945.2403
... A18: =YEAR(C18) -> 2022 | B18: ="Q"&(QUOTIENT(MONTH(C18),3.1)+1) -> Q4 | C18: 44835 | G18: 300 | K18: =L18+M18 -> 8645.2403 | L18: =Financiamento!D27 -> 4280.2364 | M18: =Financiamento!C27 -> 4365.004 | Q18: =D18 -> 0 | R18: =-SUM(F18:I18) -> -300 | S18: =SUM(Q18:R18) -> -300 | U18: =SUM(S18:T18) -> -300 | V18: =-M18 -> -4365.004 | W18: =SUM(U18:V18) -> -4665.004 | X18: =-J18 -> 0 | Y18: =SUM(W18:X18) -> -4665.004 | AA18: =S18 -> -300 | AB18: =-O18 -> 0 | AC18: =N18 -> 0 | AD18: =-K18 -> -8645.2403 | AE18: =SUM(AA18:AD18) -> -8945.2403 | AF18: =AG17 -> -125233.36 | AG18: =AF18+AE18 -> -134178.61 | AI18: 2035 | AJ18: =SUMIFS($Q$4:$Q$176,$A$4:$A$176,$AI18) -> #NAME? | AK18: =SUMIFS($Y$4:$Y$176,$A$4:$A$176,$AI18) -> #NAME? | AL18: =SUMIFS($S$4:$S$176,$A$4:$A$176,$AI18) -> #NAME? | AM18: =SUMIFS($AE$4:$AE$176,$A$4:$A$176,$AI18) -> #NAME? | AN18: {=XLOOKUP(AI18&12,$A$4:$A$176&MONTH($C$4:$C$176),$AG$4:$AG$176)} -> #NAME? | AQ18: =AE18 -> -8945.2403 | AR18: =AQ18 -> -8945.2403
A19: =YEAR(C19) -> 2022 | B19: ="Q"&(QUOTIENT(MONTH(C19),3.1)+1) -> Q4 | C19: 44866 | G19: 300 | K19: =L19+M19 -> 8645.2403 | L19: =Financiamento!D28 -> 4346.152 | M19: =Financiamento!C28 -> 4299.0883 | Q19: =D19 -> 0 | R19: =-SUM(F19:I19) -> -300 | S19: =SUM(Q19:R19) -> -300 | U19: =SUM(S19:T19) -> -300 | V19: =-M19 -> -4299.0883 | W19: =SUM(U19:V19) -> -4599.0883 | X19: =-J19 -> 0 | Y19: =SUM(W19:X19) -> -4599.0883 | AA19: =S19 -> -300 | AB19: =-O19 -> 0 | AC19: =N19 -> 0 | AD19: =-K19 -> -8645.2403 | AE19: =SUM(AA19:AD19) -> -8945.2403 | AF19: =AG18 -> -134178.61 | AG19: =AF19+AE19 -> -143123.85 | AQ19: =AE19 -> -8945.2403 | AR19: =AQ19 -> -8945.2403
A20: =YEAR(C20) -> 2022 | B20: ="Q"&(QUOTIENT(MONTH(C20),3.1)+1) -> Q4 | C20: 44896 | G20: 300 | K20: =L20+M20 -> 8645.2403 | L20: =Financiamento!D29 -> 4413.0828 | M20: =Financiamento!C29 -> 4232.1576 | Q20: =D20 -> 0 | R20: =-SUM(F20:I20) -> -300 | S20: =SUM(Q20:R20) -> -300 | U20: =SUM(S20:T20) -> -300 | V20: =-M20 -> -4232.1576 | W20: =SUM(U20:V20) -> -4532.1576 | X20: =-J20 -> 0 | Y20: =SUM(W20:X20) -> -4532.1576 | AA20: =S20 -> -300 | AB20: =-O20 -> 0 | AC20: =N20 -> 0 | AD20: =-K20 -> -8645.2403 | AE20: =SUM(AA20:AD20) -> -8945.2403 | AF20: =AG19 -> -143123.85 | AG20: =AF20+AE20 -> -152069.09 | AQ20: =AE20 -> -8945.2403 | AR20: =AQ20 -> -8945.2403
A21: =YEAR(C21) -> 2023 | B21: ="Q"&(QUOTIENT(MONTH(C21),3.1)+1) -> Q1 | C21: 44927 | G21: 300 | K21: =L21+M21 -> 8645.2403 | L21: =Financiamento!D30 -> 4481.0442 | M21: =Financiamento!C30 -> 4164.1961 | Q21: =D21 -> 0 | R21: =-SUM(F21:I21) -> -300 | S21: =SUM(Q21:R21) -> -300 | U21: =SUM(S21:T21) -> -300 | V21: =-M21 -> -4164.1961 | W21: =SUM(U21:V21) -> -4464.1961 | X21: =-J21 -> 0 | Y21: =SUM(W21:X21) -> -4464.1961 | AA21: =S21 -> -300 | AB21: =-O21 -> 0 | AC21: =N21 -> 0 | AD21: =-K21 -> -8645.2403 | AE21: =SUM(AA21:AD21) -> -8945.2403 | AF21: =AG20 -> -152069.09 | AG21: =AF21+AE21 -> -161014.33 | AQ21: =AE21 -> -8945.2403 | AR21: =AQ21 -> -8945.2403
A22: =YEAR(C22) -> 2023 | B22: ="Q"&(QUOTIENT(MONTH(C22),3.1)+1) -> Q1 | C22: 44958 | G22: 300 | K22: =L22+M22 -> 8645.2403 | L22: =Financiamento!D31 -> 4550.0523 | M22: =Financiamento!C31 -> 4095.188 | Q22: =D22 -> 0 | R22: =-SUM(F22:I22) -> -300 | S22: =SUM(Q22:R22) -> -300 | U22: =SUM(S22:T22) -> -300 | V22: =-M22 -> -4095.188 | W22: =SUM(U22:V22) -> -4395.188 | X22: =-J22 -> 0 | Y22: =SUM(W22:X22) -> -4395.188 | AA22: =S22 -> -300 | AB22: =-O22 -> 0 | AC22: =N22 -> 0 | AD22: =-K22 -> -8645.2403 | AE22: =SUM(AA22:AD22) -> -8945.2403 | AF22: =AG21 -> -161014.33 | AG22: =AF22+AE22 -> -169959.57 | AQ22: =AE22 -> -8945.2403 | AR22: =AQ22 -> -8945.2403
A23: =YEAR(C23) -> 2023 | B23: ="Q"&(QUOTIENT(MONTH(C23),3.1)+1) -> Q1 | C23: 44986 | D23: =DRE!D23 -> 6633.93 | G23: 300 | J23: =D23*6% -> 398.0358 | K23: =L23+M23 -> 8645.2403 | L23: =Financiamento!D32 -> 4620.1231 | M23: =Financiamento!C32 -> 4025.1172 | Q23: =D23 -> 6633.93 | R23: =-SUM(F23:I23) -> -300 | S23: =SUM(Q23:R23) -> 6333.93 | U23: =SUM(S23:T23) -> 6333.93 | V23: =-M23 -> -4025.1172 | W23: =SUM(U23:V23) -> 2308.8127 | X23: =-J23 -> -398.0358 | Y23: =SUM(W23:X23) -> 1910.777 | AA23: =S23 -> 6333.93 | AB23: =-O23 -> 0 | AC23: =N23 -> 0 | AD23: =-K23 -> -8645.2403 | AE23: =SUM(AA23:AD23) -> -2311.3104 | AF23: =AG22 -> -169959.57 | AG23: =AF23+AE23 -> -172270.88 | AQ23: =AE23 -> -2311.3104 | AR23: =AQ23 -> -2311.3104
A24: =YEAR(C24) -> 2023 | B24: ="Q"&(QUOTIENT(MONTH(C24),3.1)+1) -> Q2 | C24: 45017 | D24: =DRE!D24 -> 4801.7427 | G24: 300 | J24: =D24*6% -> 288.10456 | K24: =L24+M24 -> 8645.2403 | L24: =Financiamento!D33 -> 4691.273 | M24: =Financiamento!C33 -> 3953.9673 | Q24: =D24 -> 4801.7427 | R24: =-SUM(F24:I24) -> -300 | S24: =SUM(Q24:R24) -> 4501.7427 | U24: =SUM(S24:T24) -> 4501.7427 | V24: =-M24 -> -3953.9673 | W24: =SUM(U24:V24) -> 547.77538 | X24: =-J24 -> -288.10456 | Y24: =SUM(W24:X24) -> 259.67081 | AA24: =S24 -> 4501.7427 | AB24: =-O24 -> 0 | AC24: =N24 -> 0 | AD24: =-K24 -> -8645.2403 | AE24: =SUM(AA24:AD24) -> -4143.4976 | AF24: =AG23 -> -172270.88 | AG24: =AF24+AE24 -> -176414.37 | AQ24: =AE24 -> -4143.4976 | AR24: =AQ24 -> -4143.4976
A25: =YEAR(C25) -> 2023 | B25: ="Q"&(QUOTIENT(MONTH(C25),3.1)+1) -> Q2 | C25: 45047 | D25: =DRE!D25 -> 5583.9064 | G25: 300 | J25: =D25*6% -> 335.03438 | K25: =L25+M25 -> 8645.2403 | L25: =Financiamento!D34 -> 4763.5186 | M25: =Financiamento!C34 -> 3881.7217 | Q25: =D25 -> 5583.9064 | R25: =-SUM(F25:I25) -> -300 | S25: =SUM(Q25:R25) -> 5283.9064 | U25: =SUM(S25:T25) -> 5283.9064 | V25: =-M25 -> -3881.7217 | W25: =SUM(U25:V25) -> 1402.1847 | X25: =-J25 -> -335.03438 | Y25: =SUM(W25:X25) -> 1067.1503 | AA25: =S25 -> 5283.9064 | AB25: =-O25 -> 0 | AC25: =N25 -> 0 | AD25: =-K25 -> -8645.2403 | AE25: =SUM(AA25:AD25) -> -3361.334 | AF25: =AG24 -> -176414.37 | AG25: =AF25+AE25 -> -179775.71 | AQ25: =AE25 -> -3361.334 | AR25: =AQ25 -> -3361.334
A26: =YEAR(C26) -> 2023 | B26: ="Q"&(QUOTIENT(MONTH(C26),3.1)+1) -> Q2 | C26: 45078 | D26: =DRE!D26 -> 4018.4622 | G26: 300 | J26: =D26*6% -> 241.10773 | K26: =L26+M26 -> 8645.2403 | L26: =Financiamento!D35 -> 4836.8768 | M26: =Financiamento!C35 -> 3808.3635 | Q26: =D26 -> 4018.4622 | R26: =-SUM(F26:I26) -> -300 | S26: =SUM(Q26:R26) -> 3718.4622 | U26: =SUM(S26:T26) -> 3718.4622 | V26: =-M26 -> -3808.3635 | W26: =SUM(U26:V26) -> -89.901362 | X26: =-J26 -> -241.10773 | Y26: =SUM(W26:X26) -> -331.00909 | AA26: =S26 -> 3718.4622 | AB26: =-O26 -> 0 | AC26: =N26 -> 0 | AD26: =-K26 -> -8645.2403 | AE26: =SUM(AA26:AD26) -> -4926.7782 | AF26: =AG25 -> -179775.71 | AG26: =AF26+AE26 -> -184702.49 | AQ26: =AE26 -> -4926.7782 | AR26: =AQ26 -> -4926.7782
A27: =YEAR(C27) -> 2023 | B27: ="Q"&(QUOTIENT(MONTH(C27),3.1)+1) -> Q3 | C27: 45108 | D27: =DRE!D27 -> 3394.6012 | G27: 300 | J27: =D27*6% -> 203.67607 | K27: =L27+M27 -> 8645.2403 | L27: =Financiamento!D36 -> 4911.3647 | M27: =Financiamento!C36 -> 3733.8756 | Q27: =D27 -> 3394.6012 | R27: =-SUM(F27:I27) -> -300 | S27: =SUM(Q27:R27) -> 3094.6012 | U27: =SUM(S27:T27) -> 3094.6012 | V27: =-M27 -> -3733.8756 | W27: =SUM(U27:V27) -> -639.27447 | X27: =-J27 -> -203.67607 | Y27: =SUM(W27:X27) -> -842.95054 | AA27: =S27 -> 3094.6012 | AB27: =-O27 -> 0 | AC27: =N27 -> 0 | AD27: =-K27 -> -8645.2403 | AE27: =SUM(AA27:AD27) -> -5550.6392 | AF27: =AG26 -> -184702.49 | AG27: =AF27+AE27 -> -190253.13 | AQ27: =AE27 -> -5550.6392 | AR27: =AQ27 -> -5550.6392
A28: =YEAR(C28) -> 2023 | B28: ="Q"&(QUOTIENT(MONTH(C28),3.1)+1) -> Q3 | C28: 45139 | D28: =DRE!D28 -> 3812.6327 | F28: 1700 | G28: 300 | H28: 236.27 | J28: =D28*6% -> 228.75796 | K28: =L28+M28 -> 8645.2403 | L28: =Financiamento!D37 -> 4986.9997 | M28: =Financiamento!C37 -> 3658.2406 | Q28: =D28 -> 3812.6327 | R28: =-SUM(F28:I28) -> -2236.27 | S28: =SUM(Q28:R28) -> 1576.3627 | U28: =SUM(S28:T28) -> 1576.3627 | V28: =-M28 -> -3658.2406 | W28: =SUM(U28:V28) -> -2081.8779 | X28: =-J28 -> -228.75796 | Y28: =SUM(W28:X28) -> -2310.6358 | AA28: =S28 -> 1576.3627 | AB28: =-O28 -> 0 | AC28: =N28 -> 0 | AD28: =-K28 -> -8645.2403 | AE28: =SUM(AA28:AD28) -> -7068.8776 | AF28: =AG27 -> -190253.13 | AG28: =AF28+AE28 -> -197322 | AQ28: =AE28 -> -7068.8776 | AR28: =AQ28 -> -7068.8776
A29: =YEAR(C29) -> 2023 | B29: ="Q"&(QUOTIENT(MONTH(C29),3.1)+1) -> Q3 | C29: 45170 | D29: =DRE!D29 -> 4381.9087 | G29: 300 | J29: =D29*6% -> 262.91452 | K29: =L29+M29 -> 8645.2403 | L29: =Financiamento!D38 -> 5063.7995 | M29: =Financiamento!C38 -> 3581.4408 | Q29: =D29 -> 4381.9087 | R29: =-SUM(F29:I29) -> -300 | S29: =SUM(Q29:R29) -> 4081.9087 | U29: =SUM(S29:T29) -> 4081.9087 | V29: =-M29 -> -3581.4408 | W29: =SUM(U29:V29) -> 500.46784 | X29: =-J29 -> -262.91452 | Y29: =SUM(W29:X29) -> 237.55332 | AA29: =S29 -> 4081.9087 | AB29: =-O29 -> 0 | AC29: =N29 -> 0 | AD29: =-K29 -> -8645.2403 | AE29: =SUM(AA29:AD29) -> -4563.3317 | AF29: =AG28 -> -197322 | AG29: =AF29+AE29 -> -201885.34 | AQ29: =AE29 -> -4563.3317 | AR29: =AQ29 -> -4563.3317
A30: =YEAR(C30) -> 2023 | B30: ="Q"&(QUOTIENT(MONTH(C30),3.1)+1) -> Q4 | C30: 45200 | D30: =DRE!D30 -> 4485.1539 | G30: 300 | J30: =D30*6% -> 269.10923 | K30: =L30+M30 -> 8645.2403 | L30: =Financiamento!D39 -> 5141.782 | M30: =Financiamento!C39 -> 3503.4583 | Q30: =D30 -> 4485.1539 | R30: =-SUM(F30:I30) -> -300 | S30: =SUM(Q30:R30) -> 4185.1539 | U30: =SUM(S30:T30) -> 4185.1539 | V30: =-M30 -> -3503.4583 | W30: =SUM(U30:V30) -> 681.69556 | X30: =-J30 -> -269.10923 | Y30: =SUM(W30:X30) -> 412.58633 | AA30: =S30 -> 4185.1539 | AB30: =-O30 -> 0 | AC30: =N30 -> 0 | AD30: =-K30 -> -8645.2403 | AE30: =SUM(AA30:AD30) -> -4460.0865 | AF30: =AG29 -> -201885.34 | AG30: =AF30+AE30 -> -206345.42 | AQ30: =AE30 -> -4460.0865 | AR30: =AQ30 -> -4460.0865
A31: =YEAR(C31) -> 2023 | B31: ="Q"&(QUOTIENT(MONTH(C31),3.1)+1) -> Q4 | C31: 45231 | D31: =DRE!D31 -> 5180.3796 | G31: 300 | J31: =D31*6% -> 310.82278 | K31: =L31+M31 -> 8645.2403 | L31: =Financiamento!D40 -> 5220.9655 | M31: =Financiamento!C40 -> 3424.2749 | Q31: =D31 -> 5180.3796 | R31: =-SUM(F31:I31) -> -300 | S31: =SUM(Q31:R31) -> 4880.3796 | U31: =SUM(S31:T31) -> 4880.3796 | V31: =-M31 -> -3424.2749 | W31: =SUM(U31:V31) -> 1456.1048 | X31: =-J31 -> -310.82278 | Y31: =SUM(W31:X31) -> 1145.282 | AA31: =S31 -> 4880.3796 | AB31: =-O31 -> 0 | AC31: =N31 -> 0 | AD31: =-K31 -> -8645.2403 | AE31: =SUM(AA31:AD31) -> -3764.8607 | AF31: =AG30 -> -206345.42 | AG31: =AF31+AE31 -> -210110.28 | AQ31: =AE31 -> -3764.8607 | AR31: =AQ31 -> -3764.8607
A32: =YEAR(C32) -> 2023 | B32: ="Q"&(QUOTIENT(MONTH(C32),3.1)+1) -> Q4 | C32: 45261 | D32: =DRE!D32 -> 4679.9759 | G32: 300 | H32: 1129.75 | I32: 720 | J32: =D32*6% -> 280.79855 | K32: =L32+M32 -> 8645.2403 | L32: =Financiamento!D41 -> 5301.3684 | M32: =Financiamento!C41 -> 3343.872 | Q32: =D32 -> 4679.9759 | R32: =-SUM(F32:I32) -> -2149.75 | S32: =SUM(Q32:R32) -> 2530.2259 | U32: =SUM(S32:T32) -> 2530.2259 | V32: =-M32 -> -3343.872 | W32: =SUM(U32:V32) -> -813.64614 | X32: =-J32 -> -280.79855 | Y32: =SUM(W32:X32) -> -1094.4447 | AA32: =S32 -> 2530.2259 | AB32: =-O32 -> 0 | AC32: =N32 -> 0 | AD32: =-K32 -> -8645.2403 | AE32: =SUM(AA32:AD32) -> -6115.0145 | AF32: =AG31 -> -210110.28 | AG32: =AF32+AE32 -> -216225.3 | AQ32: =AE32 -> -6115.0145 | AR32: =AQ32 -> -6115.0145
A33: =YEAR(C33) -> 2024 | B33: ="Q"&(QUOTIENT(MONTH(C33),3.1)+1) -> Q1 | C33: 45292 | D33: =DRE!D33 -> 4204.0459 | G33: 300 | J33: =D33*6% -> 252.24275 | K33: =L33+M33 -> 8645.2403 | L33: =Financiamento!D42 -> 5383.0094 | M33: =Financiamento!C42 -> 3262.2309 | Q33: =D33 -> 4204.0459 | R33: =-SUM(F33:I33) -> -300 | S33: =SUM(Q33:R33) -> 3904.0459 | U33: =SUM(S33:T33) -> 3904.0459 | V33: =-M33 -> -3262.2309 | W33: =SUM(U33:V33) -> 641.81497 | X33: =-J33 -> -252.24275 | Y33: =SUM(W33:X33) -> 389.57222 | AA33: =S33 -> 3904.0459 | AB33: =-O33 -> 0 | AC33: =N33 -> 0 | AD33: =-K33 -> -8645.2403 | AE33: =SUM(AA33:AD33) -> -4741.1945 | AF33: =AG32 -> -216225.3 | AG33: =AF33+AE33 -> -220966.49 | AQ33: =AE33 -> -4741.1945 | AR33: =AQ33 -> -4741.1945
A34: =YEAR(C34) -> 2024 | B34: ="Q"&(QUOTIENT(MONTH(C34),3.1)+1) -> Q1 | C34: 45323 | D34: =DRE!D34 -> 5809.9943 | G34: 300 | J34: =D34*6% -> 348.59966 | K34: =L34+M34 -> 8645.2403 | L34: =Financiamento!D43 -> 5465.9078 | M34: =Financiamento!C43 -> 3179.3326 | Q34: =D34 -> 5809.9943 | R34: =-SUM(F34:I34) -> -300 | S34: =SUM(Q34:R34) -> 5509.9943 | U34: =SUM(S34:T34) -> 5509.9943 | V34: =-M34 -> -3179.3326 | W34: =SUM(U34:V34) -> 2330.6617 | X34: =-J34 -> -348.59966 | Y34: =SUM(W34:X34) -> 1982.0621 | AA34: =S34 -> 5509.9943 | AB34: =-O34 -> 0 | AC34: =N34 -> 0 | AD34: =-K34 -> -8645.2403 | AE34: =SUM(AA34:AD34) -> -3135.246 | AF34: =AG33 -> -220966.49 | AG34: =AF34+AE34 -> -224101.74 | AQ34: =AE34 -> -3135.246 | AR34: =AQ34 -> -3135.246
A35: =YEAR(C35) -> 2024 | B35: ="Q"&(QUOTIENT(MONTH(C35),3.1)+1) -> Q1 | C35: 45352 | D35: =DRE!D35 -> 6923.6927 | G35: 300 | J35: =D35*6% -> 415.42156 | K35: =L35+M35 -> 8645.2403 | L35: =Financiamento!D44 -> 5550.0827 | M35: =Financiamento!C44 -> 3095.1576 | Q35: =D35 -> 6923.6927 | R35: =-SUM(F35:I35) -> -300 | S35: =SUM(Q35:R35) -> 6623.6927 | U35: =SUM(S35:T35) -> 6623.6927 | V35: =-M35 -> -3095.1576 | W35: =SUM(U35:V35) -> 3528.5351 | X35: =-J35 -> -415.42156 | Y35: =SUM(W35:X35) -> 3113.1136 | AA35: =S35 -> 6623.6927 | AB35: =-O35 -> 0 | AC35: =N35 -> 0 | AD35: =-K35 -> -8645.2403 | AE35: =SUM(AA35:AD35) -> -2021.5476 | AF35: =AG34 -> -224101.74 | AG35: =AF35+AE35 -> -226123.28 | AQ35: =AE35 -> -2021.5476 | AR35: =AQ35 -> -2021.5476
A36: =YEAR(C36) -> 2024 | B36: ="Q"&(QUOTIENT(MONTH(C36),3.1)+1) -> Q2 | C36: 45383 | D36: =DRE!D36 -> 5791.3046 | G36: 300 | J36: =D36*6% -> 347.47828 | K36: =L36+M36 -> 8645.2403 | L36: =Financiamento!D45 -> 5635.554 | M36: =Financiamento!C45 -> 3009.6863 | Q36: =D36 -> 5791.3046 | R36: =-SUM(F36:I36) -> -300 | S36: =SUM(Q36:R36) -> 5491.3046 | U36: =SUM(S36:T36) -> 5491.3046 | V36: =-M36 -> -3009.6863 | W36: =SUM(U36:V36) -> 2481.6183 | X36: =-J36 -> -347.47828 | Y36: =SUM(W36:X36) -> 2134.14 | AA36: =S36 -> 5491.3046 | AB36: =-O36 -> 0 | AC36: =N36 -> 0 | AD36: =-K36 -> -8645.2403 | AE36: =SUM(AA36:AD36) -> -3153.9357 | AF36: =AG35 -> -226123.28 | AG36: =AF36+AE36 -> -229277.22 | AQ36: =AE36 -> -3153.9357 | AR36: =AQ36 -> -3153.9357
A37: =YEAR(C37) -> 2024 | B37: ="Q"&(QUOTIENT(MONTH(C37),3.1)+1) -> Q2 | C37: 45413 | D37: =DRE!D37 -> 6448.4677 | G37: 300 | I37: 754 | J37: =D37*6% -> 386.90806 | K37: =L37+M37 -> 8645.2403 | L37: =Financiamento!D46 -> 5722.3416 | M37: =Financiamento!C46 -> 2922.8988 | Q37: =D37 -> 6448.4677 | R37: =-SUM(F37:I37) -> -1054 | S37: =SUM(Q37:R37) -> 5394.4677 | U37: =SUM(S37:T37) -> 5394.4677 | V37: =-M37 -> -2922.8988 | W37: =SUM(U37:V37) -> 2471.5689 | X37: =-J37 -> -386.90806 | Y37: =SUM(W37:X37) -> 2084.6608 | AA37: =S37 -> 5394.4677 | AB37: =-O37 -> 0 | AC37: =N37 -> 0 | AD37: =-K37 -> -8645.2403 | AE37: =SUM(AA37:AD37) -> -3250.7727 | AF37: =AG36 -> -229277.22 | AG37: =AF37+AE37 -> -232527.99 | AQ37: =AE37 -> -3250.7727 | AR37: =AQ37 -> -3250.7727
A38: =YEAR(C38) -> 2024 | B38: ="Q"&(QUOTIENT(MONTH(C38),3.1)+1) -> Q2 | C38: 45444 | D38: =DRE!D38 -> 4421.3115 | G38: 300 | J38: =D38*6% -> 265.27869 | K38: =L38+M38 -> 8645.2403 | L38: =Financiamento!D47 -> 5810.4656 | M38: =Financiamento!C47 -> 2834.7747 | Q38: =D38 -> 4421.3115 | R38: =-SUM(F38:I38) -> -300 | S38: =SUM(Q38:R38) -> 4121.3115 | U38: =SUM(S38:T38) -> 4121.3115 | V38: =-M38 -> -2834.7747 | W38: =SUM(U38:V38) -> 1286.5367 | X38: =-J38 -> -265.27869 | Y38: =SUM(W38:X38) -> 1021.258 | AA38: =S38 -> 4121.3115 | AB38: =-O38 -> 0 | AC38: =N38 -> 0 | AD38: =-K38 -> -8645.2403 | AE38: =SUM(AA38:AD38) -> -4523.9289 | AF38: =AG37 -> -232527.99 | AG38: =AF38+AE38 -> -237051.92 | AQ38: =AE38 -> -4523.9289 | AR38: =AQ38 -> -4523.9289
A39: =YEAR(C39) -> 2024 | B39: ="Q"&(QUOTIENT(MONTH(C39),3.1)+1) -> Q3 | C39: 45474 | D39: =DRE!D39 -> 3192.3306 | G39: 300 | J39: =D39*6% -> 191.53984 | K39: =L39+M39 -> 8645.2403 | L39: =Financiamento!D48 -> 5899.9468 | M39: =Financiamento!C48 -> 2745.2936 | Q39: =D39 -> 3192.3306 | R39: =-SUM(F39:I39) -> -300 | S39: =SUM(Q39:R39) -> 2892.3306 | U39: =SUM(S39:T39) -> 2892.3306 | V39: =-M39 -> -2745.2936 | W39: =SUM(U39:V39) -> 147.03709 | X39: =-J39 -> -191.53984 | Y39: =SUM(W39:X39) -> -44.502746 | AA39: =S39 -> 2892.3306 | AB39: =-O39 -> 0 | AC39: =N39 -> 0 | AD39: =-K39 -> -8645.2403 | AE39: =SUM(AA39:AD39) -> -5752.9097 | AF39: =AG38 -> -237051.92 | AG39: =AF39+AE39 -> -242804.83 | AQ39: =AE39 -> -5752.9097 | AR39: =AQ39 -> -5752.9097
A40: =YEAR(C40) -> 2024 | B40: ="Q"&(QUOTIENT(MONTH(C40),3.1)+1) -> Q3 | C40: 45505 | D40: =DRE!D40 -> 4415.5447 | G40: 300 | J40: =D40*6% -> 264.93268 | K40: =L40+M40 -> 8645.2403 | L40: =Financiamento!D49 -> 5990.806 | M40: =Financiamento!C49 -> 2654.4344 | Q40: =D40 -> 4415.5447 | R40: =-SUM(F40:I40) -> -300 | S40: =SUM(Q40:R40) -> 4115.5447 | U40: =SUM(S40:T40) -> 4115.5447 | V40: =-M40 -> -2654.4344 | W40: =SUM(U40:V40) -> 1461.1103 | X40: =-J40 -> -264.93268 | Y40: =SUM(W40:X40) -> 1196.1776 | AA40: =S40 -> 4115.5447 | AB40: =-O40 -> 0 | AC40: =N40 -> 0 | AD40: =-K40 -> -8645.2403 | AE40: =SUM(AA40:AD40) -> -4529.6957 | AF40: =AG39 -> -242804.83 | AG40: =AF40+AE40 -> -247334.53 | AQ40: =AE40 -> -4529.6957 | AR40: =AQ40 -> -4529.6957
